<!--
Created: Mon Aug 26 2019 15:14:20 GMT+0800 (China Standard Time)
Modified: Thu Apr 16 2020 18:17:26 GMT+0800 (China Standard Time)
-->

# Promise

## es6 的Promise

Promise是一个构造函数. 在函数内有all, race, reject, resolve

``` js
var n = 1;
var p = new Promise(function(resolve, reject) {
  //做一些异步操作
  setTimeout(function() {
    n = n + 1;
    console.log(n);
    resolve(n);
  }, 2000);
});
```

运行结果: 

> 2

其中resolve将Promise状态从Pending变为fullfiled(实现), reject将Promise状态变成rejected(失败)

### resolve

这个对象在创建的阶段就立刻执行了方法, 因此需要在外层包裹一个函数使用.

``` js
var n = 1;
var aysnc = () => {
  var p = new Promise(function(resolve, reject) {
    //做一些异步操作
    setTimeout(function() {
      n = n + 1;
      console.log(n);
      resolve(n);
    }, 2000);
  });
  return p;
}
aysnc();
```

   
将p返回出来, 则可以调用.then(callb())方法, callb()将会获得resolve里的参数, 

``` js
aysnc().then(function(e) {
  e = e + 1;
  console.log(e); //3
});
```

这其实就是回调函数的一个实现, 类似的, 我们也可以写出: 

``` js
var n = 1;
var protest = (callback) => {
  n = n + 1;
  callback(n);
}

function add() {
  e = e + 1;
  console.log(e); //3
}
protest(add);
```

但一旦出现多层回调, 就会使得代码复杂度变大, 阅读性变差, Promise可以继续用then方法对上次返回Promise对象继续执行操作(类似链式操作).

``` js
var n = 1;
var aysnc1 = () => {
  var p = new Promise(function(resolve, reject) {
    //做一些异步操作
    setTimeout(function() {
      n = n + 1;
      console.log(n);
      resolve(n);
    }, 2000);
  });
  return p;
}
aysnc1().then((e) => {
  console.log(e);
  return aysnc2();
  //这个函数与aysnc1是类似的, 返回一个新定义的Promise对象
}).then((e) => {
  console.log(e);
})
```

### reject

``` js
var aysnc1 = () => {
  var p = new Promise(function(resolve, reject) {
    //做一些异步操作
    Math.random() - 0.5 > 0 ? resolve(1) : reject(2)
  });
  return p;
}
aysnc1().then(
  (e) => {
    console.log(e);
  },
  //1
  (e) => {
    console.log(e);
  }
  //2, 随机输出1或者2
)
```

> reject和resolve不会中断函数的运行, 可以使用return resolove()来中断函数.

### then

是resolve的处理函数, then的参数是一个函数, 该函数的参数就是之前的resolve传递的参数, then的返回值可以是一个值或者Promise.

### catch

`catch` 与 `trycatch` 类似可以用来将代码中的错误抛出, 而不阻塞代码, 同时也可以作为reject的回调, 返回值也是一个Promise或者Promise.

``` js
aysn1().then(
  (e) => {
    console.log(e);
  }).catch(
  (e) => {
    console.log(e);
  })
```

说起来都太抽象了, 用个例子来说明

#### 栗子时间

``` js
let areif = 1;
let breif = 1;
const are = (resolve, reject) => {
  return new Promise((resolve, reject) => {
    setTimeout(() => {
      if (areif) {
        resolve(1)
      } else {
        reject(2)
      }
    }, 100);
  })
}
const bre = (resolve, reject) => {
  return new Promise((resolve, reject) => {
    setTimeout(() => {
      if (breif) {
        resolve(3)
      } else {
        reject(4)
      }
    })
  })
}
are().then(a => {
  console.log(a)
  // 1
  return bre()
}).then(b => {
  console.log(b)
  // 3
}).catch(b => {
  console.log(b)
  // 无, 如果breif为0, 则输出4
})
// 返回一个值
are().then(a => {
  return 1
}).then(b => {
  console.log(b)
  // 1
})
// 出现异常
are().then(a => {
  throw new Error('hello')
}).then(b => {
  console.log(b)
}).then(b => {
  throw new Error('goodbye')
}).catch(n => {
  console.log(b)
})
//输出还是 Error: hello
// catch 在捕获到异常后, 即使后面出现异常也不会执行了.
```

那么如果再reject的时候抛出异常会怎样呢? 

``` js
const foo = (resolve, reject) => {
  return new Promise((resolve, reject) => {
    setTimeout(() => {
      if (0) {
        return resolve(1)
      } else {
        console.log('rbe')
        throw new Error('good')
        reject(2)
      }
    }, 100);
  })
}
foo().catch(b => {
  console.log(b)
})
```

这个方法会报错 `Uncaught Error: good` 

### all

``` js
const p = Promise.all([a1, a2, a3])
```

接受多个Promise , 且在a1, a2, a3都变成fulfilled的时候, p变成fulfilled, 将a1, a2, a3的返回值组成一个数组, 传递给p

只要a1、a2、a3之中有一个被rejected, p的状态就变成rejected, 此时第一个被reject的实例的返回值, 会传递给p的回调函数

### race

``` js
const p = Promise.race([a1, a2, a3])
```

如果all是且, 那么race就是或了, 在a1或a2或a3变成fulfilled或者rejected的时候, p就变成fulfilled或者rejected, 将最早fulfilled或者rejected的结果作为返回值, 传递给p.

可以利用这个方法, 随时来停止Promise.

``` js
function getWithCancel(promise, token) {
  Promise.race([promise, new Promise((_, reject) => {
    token.cancel = function() {
      return reject(new Error('cancel'))
    }
  })]).catch((e) => {
    console.log(e)
  })
};
var token = {};
var promise = () => {
  return new Promise(function(resolve, reject) {
    setTimeout(function() {
      return resolve(123)
      console.log(321);
    }, 1000)
  })
}
getWithCancel(promise(), token)
// Error: cancel
token.cancel()
```

## Promise.allSettled()

`Promise.allSettled()` 方法接受一组 Promise 实例作为参数, 包装成一个新的 Promise 实例. 只有等到所有这些参数实例都返回结果, 不管是fulfilled还是rejected, 包装实例才会结束. 该方法由 ES2020 引入.

``` JS
// JavaScript
const resolved = Promise.resolve(42);
const rejected = Promise.reject(-1);

const allSettledPromise = Promise.allSettled([resolved, rejected]);

allSettledPromise.then(function(results) {
  console.log(results);
});
// [
//    { status: 'fulfilled', value: 42 },
//    { status: 'rejected', reason: -1 }
// ]
```

### done

Promise的回调链最后一个方法抛出错误都是有可能无法捕捉到的, 因为Promise的内部错误不会冒泡到全局, 因此可以提供一个done方法来保证抛出任何有可能出现的错误.

``` js
Promise.prototype.done = function(onFulfilled, onRejected) {
  this.then(onFulfilled, onRejected).catch(function(reason) {
    setTimeout(() => {
      throw reason
    }, 0)
  });
}
```

